Traceback (most recent call last):
  File "/usr/share/miniconda/envs/gtbook/lib/python3.8/site-packages/jupyter_cache/executors/utils.py", line 51, in single_nb_execution
    executenb(
  File "/usr/share/miniconda/envs/gtbook/lib/python3.8/site-packages/nbclient/client.py", line 1204, in execute
    return NotebookClient(nb=nb, resources=resources, km=km, **kwargs).execute()
  File "/usr/share/miniconda/envs/gtbook/lib/python3.8/site-packages/nbclient/util.py", line 84, in wrapped
    return just_run(coro(*args, **kwargs))
  File "/usr/share/miniconda/envs/gtbook/lib/python3.8/site-packages/nbclient/util.py", line 62, in just_run
    return loop.run_until_complete(coro)
  File "/usr/share/miniconda/envs/gtbook/lib/python3.8/asyncio/base_events.py", line 616, in run_until_complete
    return future.result()
  File "/usr/share/miniconda/envs/gtbook/lib/python3.8/site-packages/nbclient/client.py", line 663, in async_execute
    await self.async_execute_cell(
  File "/usr/share/miniconda/envs/gtbook/lib/python3.8/site-packages/nbclient/client.py", line 965, in async_execute_cell
    await self._check_raise_for_error(cell, cell_index, exec_reply)
  File "/usr/share/miniconda/envs/gtbook/lib/python3.8/site-packages/nbclient/client.py", line 862, in _check_raise_for_error
    raise CellExecutionError.from_cell_and_msg(cell, exec_reply_content)
nbclient.exceptions.CellExecutionError: An error occurred while executing the following cell:
------------------
import PIL
import math
import requests
import numpy as np
import plotly.express as px
import plotly.graph_objects as go
# try:
#     import google.colab
# except:
#     import plotly.io as pio
#     pio.renderers.default = "png"

import gtsam 
from gtbook import diffdrive
from gtbook.html import ROW

FIG5 = "https://raw.githubusercontent.com/gtbook/robotics/main/Figures5"

------------------

[0;31m---------------------------------------------------------------------------[0m
[0;31mModuleNotFoundError[0m                       Traceback (most recent call last)
Input [0;32mIn [2][0m, in [0;36m<cell line: 14>[0;34m()[0m
[1;32m      7[0m [38;5;66;03m# try:[39;00m
[1;32m      8[0m [38;5;66;03m#     import google.colab[39;00m
[1;32m      9[0m [38;5;66;03m# except:[39;00m
[1;32m     10[0m [38;5;66;03m#     import plotly.io as pio[39;00m
[1;32m     11[0m [38;5;66;03m#     pio.renderers.default = "png"[39;00m
[1;32m     13[0m [38;5;28;01mimport[39;00m [38;5;21;01mgtsam[39;00m 
[0;32m---> 14[0m [38;5;28;01mfrom[39;00m [38;5;21;01mgtbook[39;00m [38;5;28;01mimport[39;00m diffdrive
[1;32m     15[0m [38;5;28;01mfrom[39;00m [38;5;21;01mgtbook[39;00m[38;5;21;01m.[39;00m[38;5;21;01mhtml[39;00m [38;5;28;01mimport[39;00m ROW
[1;32m     17[0m FIG5 [38;5;241m=[39m [38;5;124m"[39m[38;5;124mhttps://raw.githubusercontent.com/gtbook/robotics/main/Figures5[39m[38;5;124m"[39m

File [0;32m/usr/share/miniconda/envs/gtbook/lib/python3.8/site-packages/gtbook/diffdrive.py:52[0m, in [0;36m<module>[0;34m[0m
[1;32m     49[0m     [38;5;28;01mreturn[39;00m PIL[38;5;241m.[39mImage[38;5;241m.[39mopen(requests[38;5;241m.[39mget(url, stream[38;5;241m=[39m[38;5;28;01mTrue[39;00m)[38;5;241m.[39mraw)
[1;32m     51[0m [38;5;66;03m# Cell[39;00m
[0;32m---> 52[0m [38;5;28;01mimport[39;00m [38;5;21;01mtorch[39;00m
[1;32m     54[0m [38;5;28;01mdef[39;00m [38;5;21mconv2[39m([38;5;28minput[39m, [38;5;28mfilter[39m):
[1;32m     55[0m     [38;5;124;03m"""Convolve input image of shape (iW,iH) with filter of shape (kW,kH)"""[39;00m

[0;31mModuleNotFoundError[0m: No module named 'torch'
ModuleNotFoundError: No module named 'torch'

